Workbook

Sheet 表紙
AA9: 【BEEWORK】 IF詳細設計書
S17: =改訂履歴!A2 -> FN1009_004_管理者情報更新API
AI24: Ver 1.0
AG26: 安信株式会社

Sheet 1)カート情報を追加する「」
D4: 依存関係 | I4: 処理概要
I5: 1. ユーザー情報を取得する
J6: 1.1.セッションからログイン中のユーザー情報を取得する
K7: ・取得データ項目
M8: ユーザーID、受け取り日時
J9: 1.2. セッションからユーザー情報の取得結果により処理を分岐する
K10: 1.2.1. ユーザー情報の取得に成功した場合、以下の処理を行う
M11: 1.2.1.1 「2.」に進む
K12: 1.2.2. ユーザー情報の取得に失敗した場合、以下の処理を行う
M13: 1.2.2.1 …
I15: 2. カートから注文状況を取得する
J16: 2.1. Magent DBのカート情報テーブルに注文状況を取得する
K17: ・取得データ項目
M18: 注文状況
K19: ・条件（AND）
M20: ・ | N20: カート情報テーブルのユーザーID = ログイン中ユーザーのユーザーID
M21: ・ | N21: カート情報テーブルのキャンセルフラグ = 0
J22: 2.2. 取得した注文状況により処理を分岐する
K23: 1.2.1. 注文ができる場合、以下の処理を行う
M24: 1.2.1.1 「2.」に進む
K25: 1.2.2. 注文ができない場合、以下の処理を行う
M26: 1.2.2.1 …
I28: 3. カート情報を追加する
J29: 3.1. Magent DBのカート情報テーブルに購入商品の情報を追加する
I31: 4. 表示項目の値を生成する
J32: 4.1. 表示項目[商品価格]を生成する
K33: 4.1.1. カート情報のすべての 購入数 × 価格 を足し合わせたものを[商品価格]とする
J34: 4.2. 表示項目[税込価格]を生成する
K35: 4.2.1.税率を取得する
L36: 4.2.1.1. 税率マスタより以下の情報を取得する
M37: ・取得データ項目
N38: 税率
M39: ・条件（AND）
N40: ・ | O40: 税率マストの商品ID = 購入した商品の商品ID
K41: 4.2.2. 税額を生成する
L42: 4.2.2.1. [商品価格] × 税率マストの税率を税額とする
K43: 4.2.3. [商品価格]＋税額を[税込価格]とする

Sheet 改訂履歴
A1: IF詳細設計書 | S1: API倫理名 | X1: 管理者情報更新API | AP1: APIID | AU1: FN1009_004
A2: =AU1&"_"&X1 -> FN1009_004_管理者情報更新API | S2: API物理名 | X2: /adminList/userInfoUpdate | AP2: HTTPメソッド | AU2: POST
A5: NO. | B5: 版数 | G5: 更新日付 | O5: 更新者 | S5: 改訂箇所 | AF5: 改訂内容 | AR5: 改訂理由
A6: =ROW()-3 -> 3 | B6: 1 | G6: 45302 | O6: 孫 | S6: 新規作成 | AF6: 新規作成
A7: =ROW()-3 -> 4
A8: =ROW()-3 -> 5
A9: =ROW()-3 -> 6
A10: =ROW()-3 -> 7
A11: =ROW()-3 -> 8
A12: =ROW()-3 -> 9
A13: =ROW()-3 -> 10
A14: =ROW()-3 -> 11
A15: =ROW()-3 -> 12
A16: =ROW()-3 -> 13
A17: =ROW()-3 -> 14
A18: =ROW()-3 -> 15
... A34: =ROW()-3 -> 31

Sheet チェックリスト
A1: IF詳細設計書 | S1: API倫理名 | X1: =改訂履歴!X1 -> 管理者情報更新API | AP1: APIID | AU1: =改訂履歴!AU1 -> FN1009_004 | BW1: 〇
A2: =AU1&"_"&X1 -> FN1009_004_管理者情報更新API | S2: API物理名 | X2: =改訂履歴!X2 -> /adminList/userInfoUpdate | AP2: HTTPメソッド | AU2: =改訂履歴!AU2 -> POST | BW2: ×
BW3: -
A5: チェックリスト
A6: No | C6: 確認箇所 | K6: 確認点 | BR6: 確認
A7: 1 | C7: 共通バー | K7: APIID、API倫理名は正しいこと
A8: 2 | K8: API物理名、HTTPメソッドは正しいこと。API一覧.xlsxとは一致すること
A9: 4 | C9: 改訂履歴 | K9: 更新日付と更新日は正しいこと
A10: 5 | K10: 改訂の場合、改訂箇所と改訂内容は記載すること
A11: 6 | C11: IN.OUTとjson様式 | K11: リクエストメゾンドは正しいこと
A12: 7 | K12: swaggerURLは正しい記載すること
A13: 8 | K13: INとOUTの各モジュールは記載すること
A14: 9 | K14: モジュールの各項目は正しい記載すること
A15: 10 | K15: INとOUTのJSON様式は記載すること
A16: 11 | C16: 異常とエラー | K16: シート「異常とエラー」が存在します
A17: 12 | C17: 詳細処理仕様 | K17: コントローラーとメゾンドは正しい記載します
A18: 13 | K18: 概要説明と詳細処理仕様は正しい記載します
A19: 14 | C19: 参考するMapper | K19: DBアクセスの場合、シート「参考するMapper」を追加します。
A20: 15 | K20: MapperId、クエリーId、クエリータイプ、パラメータは正しい記載します
A21: 16 | K21: クエリー内容は正しい記載します。
A22: 17
A23: 18
A24: 19
A25: 20
A26: 21
A27: 22
A28: 23
A29: 24
A30: 25
A31: 26
A32: 27
A33: 28
... A36: 31

Sheet IN.OUTとjson様式
A1: IF詳細設計書 | S1: API倫理名 | X1: =改訂履歴!X1 -> 管理者情報更新API | AQ1: APIID | AV1: =改訂履歴!AU1 -> FN1009_004 | BW1: リクエストメゾンド
A2: =AV1&"_"&X1 -> FN1009_004_管理者情報更新API | S2: API物理名 | X2: =改訂履歴!X2 -> /adminList/userInfoUpdate | AQ2: HTTPメソッド | AV2: =改訂履歴!AU2 -> POST | BW2: POST | BX2: GET | BY2: DELETE | BZ2: PUT
A4: リクエストメゾンド | E4: POST | J4: swaggerURL | P4: http://localhost:8088/swagger-ui.html#/admin-list-controller/userInfoUpdateUsingPUT
A5: IN
B6: 入力パラメータ | G6: ー
A7: NO. | B7: 入力名 | N7: 入力論理名 | W7: タイプ | AC7: 型 | AG7: 桁数 | AK7: 必須 | AO7: 説明
A8: ー
B9: リクエストボディ | G9: A0002VueForm
A10: NO. | B10: 入力名 | N10: 入力論理名 | W10: タイプ | AC10: 型 | AG10: 桁数 | AK10: 必須 | AO10: 説明
A11: 1 | B11: authority | N11: 権限 | W11: String | AC11: 半角文字列 | AG11: 50 | AK11: ○
A12: 2 | B12: companyId | N12: 会社ID | W12: String | AC12: 半角文字列 | AG12: 10 | AK12: ○
A13: 3 | B13: phoneCountryCode | N13: 電話番号(国番号) | W13: String | AC13: 半角文字列 | AG13: 11 | AK13: ○
A14: 4 | B14: firstName | N14: 氏名 | W14: String | AC14: 全角文字列 | AG14: 10 | AK14: ○
A15: 5 | B15: firstNameKana | N15: 氏名(カナ) | W15: String | AC15: 全角文字列 | AG15: 10 | AK15: ○
A16: 6 | B16: lastName | N16: 姓 | W16: String | AC16: 全角文字列 | AG16: 10 | AK16: ○
A17: 7 | B17: lastNameKana | N17: 姓(カナ) | W17: String | AC17: 全角文字列 | AG17: 10 | AK17: ○
A18: 8 | B18: userPhoto | N18: 写真アドレス | W18: String | AC18: 全角文字列 | AG18: 200
A19: 9 | B19: userPwd | N19: パスワード | W19: String | AC19: 半角文字列 | AG19: 200 | AK19: ○
A20: 10 | B20: repwd | N20: パスワード確認 | W20: String | AC20: 半角文字列 | AG20: 100 | AK20: ○
A21: 11 | B21: sex | N21: 性別 | W21: String | AC21: 全角文字列 | AG21: 1 | AK21: ○
A22: 12 | B22: userId | N22: ユーザーID | W22: Integer | AC22: 半角数字 | AG22: 10 | AK22: ○
A23: 13 | B23: userMail | N23: ユーザーメール | W23: String | AC23: 半角文字列 | AG23: 50 | AK23: ○
A24: 14 | B24: userStatus | N24: ユーザー状態 | W24: String | AC24: 半角文字列 | AG24: 20
A25: 15 | B25: userTel | N25: ユーザー電話番号 | W25: String | AC25: 半角文字列 | AG25: 15 | AK25: ○
A26: JSON様式
B27: {
B28: "authority": "string",
B29: "companyId": "string",
B30: "countryZip": "string",
B31: "firstName": "string",
B32: "firstNameKana": "string",
B33: "lastName": "string",
B34: "lastNameKana": "string",
B35: "photoAddress": "string",
B36: "pwd": "string",
B37: "repwd": "string",
B38: "sex": "string",
... B43: }
A45: out
A46: NO. | B46: 出力名 | N46: 出力論理名 | W46: タイプ | AC46: 型 | AG46: 桁数 | AK46: 必須 | AO46: 説明
...

Sheet 異常とエラー
A1: IF詳細設計書 | S1: API倫理名 | X1: =改訂履歴!X1 -> 管理者情報更新API | AP1: APIID | AU1: =改訂履歴!AU1 -> FN1009_004 | BW1: リクエストメゾンド
A2: =AU1&"_"&X1 -> FN1009_004_管理者情報更新API | S2: API物理名 | X2: =改訂履歴!X2 -> /adminList/userInfoUpdate | AP2: HTTPメソッド | AU2: =改訂履歴!AU2 -> POST | BW2: POST | BX2: GET | BY2: DELETE | BZ2: PUT
A4: リクエストメゾンド | E4: =IN.OUTとjson様式!E4 -> POST | J4: swaggerURL | P4: =IN.OUTとjson様式!P4 -> http://localhost:8088/swagger-ui.html#/admin-list-controller/userInfoUpdateUsingPUT
A5: out
A6: NO. | B6: code | G6: message | W6: 説明
A7: 1 | B7: 200 | G7: 操作成功
A8: 2 | B8: 404 | G8: パラメータチェック失敗
A9: 3 | B9: 500 | G9: 操作失敗
B10: JSON様式 | AC10: タイプ | AK10: 説明
B11: {
B12: "code": 0,
B13: "data": [
B14: {
B15: }
B16: ],
B17: "message": "string"
B18: }

Sheet 詳細処理仕様
A1: IF詳細設計書 | S1: API倫理名 | X1: =改訂履歴!X1 -> 管理者情報更新API | AQ1: APIID | AV1: =改訂履歴!AU1 -> FN1009_004
A2: =AV1&"_"&X1 -> FN1009_004_管理者情報更新API | S2: API物理名 | X2: =改訂履歴!X2 -> /adminList/userInfoUpdate | AQ2: HTTPメソッド | AV2: =改訂履歴!AU2 -> POST
A5: 概要説明
A6: 個人情報を更新するために使用するAPI
A9: 詳細処理仕様
A10: コントローラー | F10: AdminListController | Z10: メソッド | AE10: userInfoUpdate
A12: 1 | C12: resultsを共通チェックします
D13: resultsがエラーが存在する場合、共通メソッドCommonResult.validateFailedでエラーをリターンします
D14: CommonResult.validateFailedのパラメータ
D15: no | G15: パラメータ | X15: タイプ | AF15: 必須
D16: 1 | G16: results.getFieldError().getDefaultMessage() | X16: String
D17: リターン
D18: タイプ | L18: 備考
D19: CommonResult<T>
A21: 2 | C21: ユーザー情報編集
D22: サービスメソッドAdminListService.editUserInfoでユーザーの情報を編集します。
D23: AdminListService.editUserInfoのパラメータ
D24: no | G24: パラメータ | X24: タイプ | AI24: 必須
D25: 1 | G25: a0002VueForm | X25: A0002VueForm
D26: リターン
D27: タイプ | O27: 備考
D28: UserTblEntity
A30: 3 | C30: ユーザーID取得
D31: A0002VueFormのユーザーIDをuserEntityに加えます。
A33: 4 | C33: ユーザー情報更新
D34: サービスメソッドAdminListService.updateUserInfoでユーザーの情報を更新します。
D35: AdminListService.updateUserInfoのパラメータ
D36: no | G36: パラメータ | X36: タイプ | AI36: 必須
D37: 1 | G37: userEntity | X37: UserTblEntity
D38: リターン
D39: タイプ | O39: 備考
D40: Integer
A42: 5 | C42: 操作結果を判断
D43: 修正したデータベースの行数を判断して、１ではない場合、共通メソッドCommonResult.failedでエラーを表示します。
D44: CommonResult.failedのパラメータ
D45: no | G45: パラメータ | X45: タイプ | AH45: 必須
D46: 1
D47: リターン
D48: タイプ | L48: 備考
D49: CommonResult<T>
...

Sheet 参考するサービス
A1: IF詳細設計書 | S1: API倫理名 | X1: =改訂履歴!X1 -> 管理者情報更新API | AQ1: APIID | AV1: =改訂履歴!AU1 -> FN1009_004
A2: =AV1&"_"&X1 -> FN1009_004_管理者情報更新API | S2: API物理名 | X2: =改訂履歴!X2 -> /adminList/userInfoUpdate | AQ2: HTTPメソッド | AV2: =改訂履歴!AU2 -> POST
A5: サービス | F5: AdminListService | AQ5: メソッド | AV5: editUserInfo
A7: 1 | C7: メソッドgetUserTblEntityで、入力した個人情報を実態対象に変換します。
D8: getUserTblEntityのパラメータ
D9: パラメータ | G9: id | AE9: タイプ | AQ9: 必須 | AU9: 説明
D10: 1 | G10: a0002VueForm | AE10: A0002VueForm | AQ10: ○
D11: リターン | G11: id | AE11: タイプ | AQ11: 必須
G12: userEntity | AE12: UserTblEntity
A16: サービス | F16: AdminListService | AQ16: メソッド | AV16: updateUserInfo
A18: 1 | C18: ユーザーデータを挿入
D19: メソッドUserTblMapper.updateUserInfoで、ユーザー情報をデータベースに加えます。
D20: UserTblMapper.updateUserInfoのパラメータ
D21: パラメータ | G21: id | AE21: タイプ | AQ21: 必須 | AU21: 説明
D22: 1 | G22: userEntity | AE22: UserTblEntity | AQ22: ○
D23: リターン | G23: id | AE23: タイプ | AQ23: 必須
AE24: Integer
D25: UserTblMapper.updateUserInfoの処理内容はシート「参考するMapper」のUserTblMapper.updateUserInfoを参考にしてください。

Sheet 参考するMapper
A1: IF詳細設計書 | S1: API倫理名 | X1: =改訂履歴!X1 -> 管理者情報更新API | AQ1: APIID | AV1: =改訂履歴!AU1 -> FN1009_004 | BW1: select
A2: =AV1&"_"&X1 -> FN1009_004_管理者情報更新API | S2: API物理名 | X2: =改訂履歴!X2 -> /adminList/userInfoUpdate | AQ2: HTTPメソッド | AV2: =改訂履歴!AU2 -> POST | BW2: update
BW3: insert
BW4: Delete
A5: MapperId | F5: UserTblMapper | W5: クエリーId | AB5: updateUserInfo | AM5: クエリータイプ | AR5: update
A6: IN
A7: フィールド | S7: 値 | AH7: where条件 | AQ7: 説明
A8: USER_TBL.USER_ID | S8: userTblEntity.userId | AH8: ○
A9: USER_TBL.PWD | S9: userTblEntity.pwd
A10: USER_TBL.COMPANY_ID | S10: userTblEntity.companyId
A11: USER_TBL.AUTHORITY | S11: userTblEntity.authority
A12: USER_TBL.FIRST_NAME_KANA | S12: userTblEntity.firstNameKana
A13: USER_TBL.FIRST_NAME | S13: userTblEntity.firstName
A14: USER_TBL.LAST_NAME_KANA | S14: userTblEntity.lastNameKana
A15: USER_TBL.LAST_NAME | S15: userTblEntity.lastName
A16: USER_TBL.SEX | S16: userTblEntity.SEX
A17: USER_TBL.COUNTRY_ZIP | S17: userTblEntity.countryZip
A18: USER_TBL.USER_TEL | S18: userTblEntity.userTel
A19: USER_TBL.USER_MAIL | S19: userTblEntity.userMail
A20: USER_TBL.PHOTO_ADDRESS | S20: userTblEntity.photoAddress
... A24: USER_TBL.UPDATE_BY | S24: userTblEntity.updateBy
A25: OUT
A26: フィールド | S26: 値 | AH26: 説明
A28: クエリー内容
C29: <update id="updateUserInfo" parameterType="Ansin.web.vueForm.A0002VueForm">
C30: UPDATE
C31: USER_TBL
C32: SET
C33: <if test="a0002VueForm.firstNameKana != null and a0002VueForm.firstNameKana != ''">
C34: FIRST_NAME_KANA = #{a0002VueForm.firstNameKana},
C35: </if>
C36: <if test="a0002VueForm.firstName != null and a0002VueForm.firstName != ''">
C37: FIRST_NAME = #{a0002VueForm.firstName},
C38: </if>
C39: <if test="a0002VueForm.lastNameKana != null and a0002VueForm.lastNameKana != ''">
C40: LAST_NAME_KANA = #{a0002VueForm.lastNameKana},
... C61: </update>
