Workbook

Sheet 表紙
AA9: 【BEEWORK】 IF詳細設計書
S17: =改訂履歴!A2 -> FN1002_002_システム管理者新規作成API
AI24: Ver 1.0
AG26: 安信株式会社

Sheet 1)カート情報を追加する「」
D4: 依存関係 | I4: 処理概要
I5: 1. ユーザー情報を取得する
J6: 1.1.セッションからログイン中のユーザー情報を取得する
K7: ・取得データ項目
M8: ユーザーID、受け取り日時
J9: 1.2. セッションからユーザー情報の取得結果により処理を分岐する
K10: 1.2.1. ユーザー情報の取得に成功した場合、以下の処理を行う
M11: 1.2.1.1 「2.」に進む
K12: 1.2.2. ユーザー情報の取得に失敗した場合、以下の処理を行う
M13: 1.2.2.1 …
I15: 2. カートから注文状況を取得する
J16: 2.1. Magent DBのカート情報テーブルに注文状況を取得する
K17: ・取得データ項目
M18: 注文状況
K19: ・条件（AND）
M20: ・ | N20: カート情報テーブルのユーザーID = ログイン中ユーザーのユーザーID
M21: ・ | N21: カート情報テーブルのキャンセルフラグ = 0
J22: 2.2. 取得した注文状況により処理を分岐する
K23: 1.2.1. 注文ができる場合、以下の処理を行う
M24: 1.2.1.1 「2.」に進む
K25: 1.2.2. 注文ができない場合、以下の処理を行う
M26: 1.2.2.1 …
I28: 3. カート情報を追加する
J29: 3.1. Magent DBのカート情報テーブルに購入商品の情報を追加する
I31: 4. 表示項目の値を生成する
J32: 4.1. 表示項目[商品価格]を生成する
K33: 4.1.1. カート情報のすべての 購入数 × 価格 を足し合わせたものを[商品価格]とする
J34: 4.2. 表示項目[税込価格]を生成する
K35: 4.2.1.税率を取得する
L36: 4.2.1.1. 税率マスタより以下の情報を取得する
M37: ・取得データ項目
N38: 税率
M39: ・条件（AND）
N40: ・ | O40: 税率マストの商品ID = 購入した商品の商品ID
K41: 4.2.2. 税額を生成する
L42: 4.2.2.1. [商品価格] × 税率マストの税率を税額とする
K43: 4.2.3. [商品価格]＋税額を[税込価格]とする

Sheet 改訂履歴
A1: IF詳細設計書 | S1: API倫理名 | X1: システム管理者新規作成API | AL1: APIID | AQ1: FN1002_002
A2: =AQ1&"_"&X1 -> FN1002_002_システム管理者新規作成API | S2: API物理名 | X2: /adminList/auserSystemInsert | AL2: HTTPメソッド | AQ2: POST
A5: NO. | B5: 版数 | G5: 更新日付 | O5: 更新者 | S5: 改訂箇所 | AF5: 改訂内容 | AR5: 改訂理由
A6: =ROW()-3 -> 3 | B6: 1 | G6: 45302 | O6: 孫 | S6: 新規作成 | AF6: 新規作成
A7: =ROW()-3 -> 4
A8: =ROW()-3 -> 5
A9: =ROW()-3 -> 6
A10: =ROW()-3 -> 7
A11: =ROW()-3 -> 8
A12: =ROW()-3 -> 9
A13: =ROW()-3 -> 10
A14: =ROW()-3 -> 11
A15: =ROW()-3 -> 12
A16: =ROW()-3 -> 13
A17: =ROW()-3 -> 14
A18: =ROW()-3 -> 15
... A34: =ROW()-3 -> 31

Sheet チェックリスト
A1: IF詳細設計書 | S1: API倫理名 | X1: =改訂履歴!X1 -> システム管理者新規作成API | AL1: APIID | AQ1: =改訂履歴!AQ1 -> FN1002_002 | BW1: 〇
A2: =AQ1&"_"&X1 -> FN1002_002_システム管理者新規作成API | S2: API物理名 | X2: =改訂履歴!X2 -> /adminList/auserSystemInsert | AL2: HTTPメソッド | AQ2: =改訂履歴!AQ2 -> POST | BW2: ×
BW3: -
A5: チェックリスト
A6: No | C6: 確認箇所 | K6: 確認点 | BR6: 確認
A7: 1 | C7: 共通バー | K7: APIID、API倫理名は正しいこと
A8: 2 | K8: API物理名、HTTPメソッドは正しいこと。API一覧.xlsxとは一致すること
A9: 4 | C9: 改訂履歴 | K9: 更新日付と更新日は正しいこと
A10: 5 | K10: 改訂の場合、改訂箇所と改訂内容は記載すること
A11: 6 | C11: IN.OUTとjson様式 | K11: リクエストメゾンドは正しいこと
A12: 7 | K12: swaggerURLは正しい記載すること
A13: 8 | K13: INとOUTの各モジュールは記載すること
A14: 9 | K14: モジュールの各項目は正しい記載すること
A15: 10 | K15: INとOUTのJSON様式は記載すること
A16: 11 | C16: 異常とエラー | K16: シート「異常とエラー」が存在します
A17: 12 | C17: 詳細処理仕様 | K17: コントローラーとメゾンドは正しい記載します
A18: 13 | K18: 概要説明と詳細処理仕様は正しい記載します
A19: 14 | C19: 参考するMapper | K19: DBアクセスの場合、シート「参考するMapper」を追加します。
A20: 15 | K20: MapperId、クエリーId、クエリータイプ、パラメータは正しい記載します
A21: 16 | K21: クエリー内容は正しい記載します。
A22: 17
A23: 18
A24: 19
A25: 20
A26: 21
A27: 22
A28: 23
A29: 24
A30: 25
A31: 26
A32: 27
A33: 28
... A36: 31

Sheet IN.OUTとjson様式
A1: IF詳細設計書 | S1: API倫理名 | X1: =改訂履歴!X1 -> システム管理者新規作成API | AL1: APIID | AQ1: =改訂履歴!AQ1 -> FN1002_002 | BW1: リクエストメゾンド
A2: =AQ1&"_"&X1 -> FN1002_002_システム管理者新規作成API | S2: API物理名 | X2: =改訂履歴!X2 -> /adminList/auserSystemInsert | AL2: HTTPメソッド | AQ2: =改訂履歴!AQ2 -> POST | BW2: POST | BX2: GET | BY2: DELETE | BZ2: PUT
A4: リクエストメゾンド | E4: POST | J4: swaggerURL | P4: http://localhost:8088/swagger-ui.html#/admin-system-register-controller/userInsertUsingPOST_1
A5: IN
B6: 入力パラメータ | G6: ー
A7: NO. | B7: 入力名 | N7: 入力論理名 | W7: タイプ | AC7: 型 | AG7: 桁数 | AK7: 必須 | AO7: 説明
A8: ー
B9: リクエストボディ | G9: A0002VueForm
A10: NO. | B10: 入力名 | N10: 入力論理名 | W10: タイプ | AC10: 型 | AG10: 桁数 | AK10: 必須 | AO10: 説明
A11: 1 | B11: authority | N11: 権限 | W11: String | AC11: 半角文字列 | AG11: 50 | AK11: ○
A12: 2 | B12: companyId | N12: 会社ID | W12: String | AC12: 半角文字列 | AG12: 10 | AK12: ○
A13: 3 | B13: COUNTRY_ZIP | N13: 電話番号(国番号) | W13: String | AC13: 半角文字列 | AG13: 11 | AK13: ○
A14: 4 | B14: firstName | N14: 氏名 | W14: String | AC14: 全角文字列 | AG14: 10 | AK14: ○
A15: 5 | B15: firstNameKana | N15: 氏名(カナ) | W15: String | AC15: 全角文字列 | AG15: 10 | AK15: ○
A16: 6 | B16: lastName | N16: 姓 | W16: String | AC16: 全角文字列 | AG16: 10 | AK16: ○
A17: 7 | B17: lastNameKana | N17: 姓(カナ) | W17: String | AC17: 全角文字列 | AG17: 10 | AK17: ○
A18: 8 | B18: userPhoto | N18: 写真アドレス | W18: String | AC18: 全角文字列 | AG18: 200
A19: 9 | B19: userPwd | N19: パスワード | W19: String | AC19: 半角文字列 | AG19: 200 | AK19: ○
A20: 10 | B20: repwd | N20: パスワード確認 | W20: String | AC20: 半角文字列 | AG20: 100 | AK20: ○
A21: 11 | B21: sex | N21: 性別 | W21: String | AC21: 全角文字列 | AG21: 1 | AK21: ○
A22: 12 | B22: userCd | N22: ユーザーID | W22: Integer | AC22: 半角数字 | AG22: 10 | AK22: ○
A23: 13 | B23: userMail | N23: ユーザーメール | W23: String | AC23: 半角文字列 | AG23: 50 | AK23: ○
A24: 14 | B24: userStatus | N24: ユーザー状態 | W24: String | AC24: 半角文字列 | AG24: 20
A25: 15 | B25: userTel | N25: ユーザー電話番号 | W25: String | AC25: 半角文字列 | AG25: 15 | AK25: ○
A26: JSON様式
B27: {
B28: "authority": "string",
B29: "companyId": "string",
B30: "countryZip": "string",
B31: "firstName": "string",
B32: "firstNameKana": "string",
B33: "lastName": "string",
B34: "lastNameKana": "string",
B35: "photoAddress": "string",
B36: "pwd": "string",
B37: "repwd": "string",
B38: "sex": "string",
... B43: }
A44: out
A45: NO. | B45: 出力名 | N45: 出力論理名 | W45: タイプ | AC45: 型 | AG45: 桁数 | AK45: 必須 | AO45: 説明
...

Sheet 異常とエラー
A1: IF詳細設計書 | S1: API倫理名 | X1: =改訂履歴!X1 -> システム管理者新規作成API | AL1: APIID | AQ1: =改訂履歴!AQ1 -> FN1002_002 | BW1: リクエストメゾンド
A2: =AQ1&"_"&X1 -> FN1002_002_システム管理者新規作成API | S2: API物理名 | X2: =改訂履歴!X2 -> /adminList/auserSystemInsert | AL2: HTTPメソッド | AQ2: =改訂履歴!AQ2 -> POST | BW2: POST | BX2: GET | BY2: DELETE | BZ2: PUT
A4: リクエストメゾンド | E4: =IN.OUTとjson様式!E4 -> POST | J4: swaggerURL | P4: =IN.OUTとjson様式!P4 -> http://localhost:8088/swagger-ui.html#/admin-system-register-controller/userInsertUsingPOST_1
A5: out
A6: NO. | B6: code | G6: message | W6: 説明
A7: 1 | B7: 200 | G7: 操作成功
A8: 2 | B8: 404 | G8: パラメータチェック失敗
A9: 3 | B9: 500 | G9: 操作失敗
B10: JSON様式 | AC10: タイプ | AK10: 説明
B11: {
B12: "code": 0,
B13: "data": [
B14: {
B15: }
B16: ],
B17: "message": "string"
B18: }

Sheet 詳細処理仕様
A1: IF詳細設計書 | S1: API倫理名 | X1: =改訂履歴!X1 -> システム管理者新規作成API | AL1: APIID | AQ1: =改訂履歴!AQ1 -> FN1002_002
A2: =AQ1&"_"&X1 -> FN1002_002_システム管理者新規作成API | S2: API物理名 | X2: =改訂履歴!X2 -> /adminList/auserSystemInsert | AL2: HTTPメソッド | AQ2: =改訂履歴!AQ2 -> POST
A5: 概要説明
A6: システム管理者を新規作成するために使用するAPI
A9: 詳細処理仕様
A10: コントローラー | F10: UserLoginController | Z10: メソッド | AE10: login
A12: 1 | C12: システム管理者情報システム管理者(認証済み)追加
D13: メソッドAdminSystemRegisterService.insertUserInfoで入力したシステム管理者情報を追加します
D14: AdminSystemRegisterService.editUserInfoのパラメータ
D15: no | G15: パラメータ | X15: タイプ | AF15: 必須
D16: 1 | G16: userEntity | X16: UserTblEntity
D17: リターン
D18: タイプ | L18: 備考
D19: int | L19: 返回插入数据库操作影响的行数
A21: 2 | C21: 1のリターン値が１か確認します
D22: リターン値が１ではない場合、共通メソッドCommonResult.failedでエラーをリターンします
D23: CommonResult.failedのパラメータ
D24: no | G24: パラメータ | X24: タイプ | AF24: 必須
D26: リターン
D27: タイプ | L27: 備考
D28: CommonResult<T>
A30: 3 | C30: 操作成功の結果を出力します
D31: メソッドCommonResult.successで「操作成功」を出力します
D32: CommonResult.successのパラメータ
D33: no | G33: パラメータ | X33: タイプ | AF33: 必須
D34: 1 | G34: ResultCode.SUCCESS.getMessage() | X34: String
D35: リターン
D36: タイプ | L36: 備考
D37: CommonResult<T>

Sheet 参考するサービス
A1: IF詳細設計書 | S1: API倫理名 | X1: =改訂履歴!X1 -> システム管理者新規作成API | AL1: APIID | AQ1: =改訂履歴!AQ1 -> FN1002_002
A2: =AQ1&"_"&X1 -> FN1002_002_システム管理者新規作成API | S2: API物理名 | X2: =改訂履歴!X2 -> /adminList/auserSystemInsert | AL2: HTTPメソッド | AQ2: =改訂履歴!AQ2 -> POST
A5: サービス | F5: AdminSystemRegisterService | Z5: メソッド | AE5: insertUserInfo
A7: 1 | C7: 入力したシステム管理者情報を追加します
D8: mapper「UserTblMapper.insertUserInfo」を利用して、データをインサートします
D9: パラメータ | G9: id | P9: タイプ | X9: 必須 | AB9: 説明
D10: 1 | G10: userEntity | P10: UserTblEntity | X10: ○
D11: リターン | G11: id | P11: タイプ | X11: 必須
D12: 1 | G12: count | P12: Integer
D13: UserTblMapper.insertUserInfoの処理内容はシート「参考するMapper」のUserTblMapper.insertUserInfoを参考にしてください。
A15: 2 | C15: UserTblMapper.insertUserInfoで修正したデータベースの行数をリターンします。

Sheet 参考するMapper
A1: IF詳細設計書 | S1: API倫理名 | X1: =改訂履歴!X1 -> システム管理者新規作成API | AL1: APIID | AQ1: =改訂履歴!AQ1 -> FN1002_002 | BW1: select
A2: =AQ1&"_"&X1 -> FN1002_002_システム管理者新規作成API | S2: API物理名 | X2: =改訂履歴!X2 -> /adminList/auserSystemInsert | AL2: HTTPメソッド | AQ2: =改訂履歴!AQ2 -> POST | BW2: update
BW3: insert
BW4: Delete
A5: MapperId | F5: UserTblMapper | W5: クエリーId | AB5: insertUserInfo | AM5: クエリータイプ | AR5: insert
A6: IN
A7: フィールド | S7: 値 | AH7: where条件 | AQ7: 説明
A8: USER_CD | S8: userTblEntity.userCd
A9: PWD | S9: userTblEntity.pwd
A10: COMPANY_ID | S10: userTblEntity.companyId
A11: AUTHORITY | S11: userTblEntity.authority
A12: FIRST_NAME_KANA | S12: userTblEntity.firstNameKana
A13: FIRST_NAME | S13: userTblEntity.firstName
A14: LAST_NAME_KANA | S14: userTblEntity.lastNameKana
A15: LAST_NAME | S15: userTblEntity.lastName
A16: SEX | S16: userTblEntity.sex
A17: COUNTRY_ZIP | S17: userTblEntity.countryZip
A18: USER_TEL | S18: userTblEntity.userTel
A19: USER_MAIL | S19: userTblEntity.userMail
... A24: UPDATE_BY | S24: userTblEntity.updateBy
A26: OUT
A27: フィールド | S27: 値 | AH27: 説明
A28: クエリー内容
C29: <insert
C30: id="insertUserInfo"
C31: parameterType="Ansin.web.entity.UserTblEntity">
C32: INSERT INTO
C33: user_tbl
C34: (
C35: <include refid="insertUserTbl"/>
C36: )
C37: VALUES
C38: (DEFAULT, #{pwd}, #{companyId}, #{authority},
C39: #{firstNameKana}, #{firstName},
C40: #{lastNameKana}, #{lastName}, #{sex},
... C46: </insert>
