Workbook

Sheet 表紙
AA9: 【BEEWORK】 IF詳細設計書
S17: =改訂履歴!A2 -> FN1009_004_管理者情報取得API
AI24: Ver 1.0
AG26: 安信株式会社

Sheet 1)カート情報を追加する「」
D4: 依存関係 | I4: 処理概要
I5: 1. ユーザー情報を取得する
J6: 1.1.セッションからログイン中のユーザー情報を取得する
K7: ・取得データ項目
M8: ユーザーID、受け取り日時
J9: 1.2. セッションからユーザー情報の取得結果により処理を分岐する
K10: 1.2.1. ユーザー情報の取得に成功した場合、以下の処理を行う
M11: 1.2.1.1 「2.」に進む
K12: 1.2.2. ユーザー情報の取得に失敗した場合、以下の処理を行う
M13: 1.2.2.1 …
I15: 2. カートから注文状況を取得する
J16: 2.1. Magent DBのカート情報テーブルに注文状況を取得する
K17: ・取得データ項目
M18: 注文状況
K19: ・条件（AND）
M20: ・ | N20: カート情報テーブルのユーザーID = ログイン中ユーザーのユーザーID
M21: ・ | N21: カート情報テーブルのキャンセルフラグ = 0
J22: 2.2. 取得した注文状況により処理を分岐する
K23: 1.2.1. 注文ができる場合、以下の処理を行う
M24: 1.2.1.1 「2.」に進む
K25: 1.2.2. 注文ができない場合、以下の処理を行う
M26: 1.2.2.1 …
I28: 3. カート情報を追加する
J29: 3.1. Magent DBのカート情報テーブルに購入商品の情報を追加する
I31: 4. 表示項目の値を生成する
J32: 4.1. 表示項目[商品価格]を生成する
K33: 4.1.1. カート情報のすべての 購入数 × 価格 を足し合わせたものを[商品価格]とする
J34: 4.2. 表示項目[税込価格]を生成する
K35: 4.2.1.税率を取得する
L36: 4.2.1.1. 税率マスタより以下の情報を取得する
M37: ・取得データ項目
N38: 税率
M39: ・条件（AND）
N40: ・ | O40: 税率マストの商品ID = 購入した商品の商品ID
K41: 4.2.2. 税額を生成する
L42: 4.2.2.1. [商品価格] × 税率マストの税率を税額とする
K43: 4.2.3. [商品価格]＋税額を[税込価格]とする

Sheet 改訂履歴
A1: IF詳細設計書 | S1: API倫理名 | X1: 管理者情報取得API | AL1: APIID | AQ1: FN1009_004 | BA1: 作成者 | BE1: =O6 -> 熊 | BL1: 作成日 | BP1: =G6 -> 45680
A2: =AQ1&"_"&X1 -> FN1009_004_管理者情報取得API | S2: API物理名 | X2: /adminList/getUserInfo | AL2: HTTPメソッド | AQ2: POST | BA2: 更新者 | BL2: 更新日
A5: NO. | B5: 版数 | G5: 更新日付 | O5: 更新者 | S5: 改訂箇所 | AF5: 改訂内容 | AR5: 改訂理由
A6: =ROW()-3 -> 3 | B6: 1 | G6: 45680 | O6: 熊 | S6: 全シート | AF6: 新規作成
A7: =ROW()-3 -> 4
A8: =ROW()-3 -> 5
A9: =ROW()-3 -> 6
A10: =ROW()-3 -> 7
A11: =ROW()-3 -> 8
A12: =ROW()-3 -> 9
A13: =ROW()-3 -> 10
A14: =ROW()-3 -> 11
A15: =ROW()-3 -> 12
A16: =ROW()-3 -> 13
A17: =ROW()-3 -> 14
A18: =ROW()-3 -> 15
... A34: =ROW()-3 -> 31

Sheet チェックリスト
A1: IF詳細設計書 | S1: API倫理名 | X1: =改訂履歴!X1 -> 管理者情報取得API | AL1: APIID | AQ1: =改訂履歴!AQ1 -> FN1009_004 | BA1: 作成者 | BE1: =改訂履歴!O6 -> 熊 | BL1: 作成日 | BP1: =改訂履歴!G6 -> 45680 | BW1: 〇
A2: =AQ1&"_"&X1 -> FN1009_004_管理者情報取得API | S2: API物理名 | X2: =改訂履歴!X2 -> /adminList/getUserInfo | AL2: HTTPメソッド | AQ2: =改訂履歴!AQ2 -> POST | BA2: 更新者 | BL2: 更新日 | BW2: ×
BW3: -
A5: チェックリスト
A6: No | C6: 確認箇所 | K6: 確認点 | BR6: 確認
A7: 1 | C7: 共通バー | K7: APIID、API倫理名は正しいこと | BR7: 〇
A8: 2 | K8: API物理名、HTTPメソッドは正しいこと。API一覧.xlsxとは一致すること | BR8: 〇
A9: 4 | C9: 改訂履歴 | K9: 更新日付と更新日は正しいこと | BR9: 〇
A10: 5 | K10: 改訂の場合、改訂箇所と改訂内容は記載すること | BR10: 〇
A11: 6 | C11: IN.OUTとjson様式 | K11: リクエストメゾンドは正しいこと | BR11: 〇
A12: 7 | K12: swaggerURLは正しい記載すること | BR12: 〇
A13: 8 | K13: INとOUTの各モジュールは記載すること | BR13: 〇
A14: 9 | K14: モジュールの各項目は正しい記載すること | BR14: 〇
A15: 10 | K15: INとOUTのJSON様式は記載すること | BR15: 〇
A16: 11 | C16: 異常とエラー | K16: シート「異常とエラー」が存在します | BR16: 〇
A17: 12 | C17: 詳細処理仕様 | K17: コントローラーとメゾンドは正しい記載します | BR17: 〇
A18: 13 | K18: 概要説明と詳細処理仕様は正しい記載します | BR18: 〇
A19: 14 | C19: 参考するMapper | K19: DBアクセスの場合、シート「参考するMapper」を追加します。 | BR19: 〇
A20: 15 | K20: MapperId、クエリーId、クエリータイプ、パラメータは正しい記載します | BR20: 〇
A21: 16 | K21: クエリー内容は正しい記載します。 | BR21: 〇
A22: 17
A23: 18
A24: 19
A25: 20
A26: 21
A27: 22
A28: 23
A29: 24
A30: 25
A31: 26
A32: 27
A33: 28
... A36: 31

Sheet IN.OUTとjson様式
A1: IF詳細設計書 | S1: API倫理名 | X1: =改訂履歴!X1 -> 管理者情報取得API | AL1: APIID | AQ1: =改訂履歴!AQ1 -> FN1009_004 | BA1: 作成者 | BE1: =改訂履歴!O6 -> 熊 | BL1: 作成日 | BP1: 45680 | BW1: リクエストメゾンド
A2: =AQ1&"_"&X1 -> FN1009_004_管理者情報取得API | S2: API物理名 | X2: =改訂履歴!X2 -> /adminList/getUserInfo | AL2: HTTPメソッド | AQ2: =改訂履歴!AQ2 -> POST | BA2: 更新者 | BL2: 更新日 | BW2: POST | BX2: GET | BY2: DELETE | BZ2: PUT
A4: リクエストメゾンド | E4: POST | J4: swaggerURL | P4: http://localhost:8088/swagger-ui.html#/admin-list-controller/getUserInfoUsingPOST
A5: IN
B6: 入力パラメータ | G6: ー
A7: NO. | B7: 入力名 | N7: 入力論理名 | W7: タイプ | AC7: 型 | AG7: 桁数 | AK7: 必須 | AO7: 説明
A8: ー
B9: リクエストボディ
A10: NO. | B10: 入力名 | N10: 入力論理名 | W10: タイプ | AC10: 型 | AG10: 桁数 | AK10: 必須 | AO10: 説明
A11: 1 | B11: userID | N11: ユーザーID | W11: 半角文字列 | AC11: String | AG11: 10 | AO11: 数字文字列
A12: JSON様式
B14: {
B15: "userID": "0",
B16: }
A19: out
A20: NO. | B20: 出力名 | N20: 出力論理名 | W20: タイプ | AC20: 型 | AG20: 桁数 | AK20: 必須 | AO20: 説明
A21: 1 | B21: code
A22: 2 | B22: message
B23: 出力モジュール | G23: A0303Vo
A24: 1 | B24: authority | N24: 権限 | W24: 半角文字列 | AC24: String | AG24: 2 | AO24: 数字文字列
A25: 2 | B25: companyId | N25: 会社ID | W25: 半角文字列 | AC25: String | AG25: 10 | AO25: 数字文字列
A26: 3 | B26: companyNm | N26: 会社名 | W26: 全角文字列 | AC26: String | AG26: 50
A27: 4 | B27: countryZip | N27: 郵便番号 | W27: 半角文字列 | AC27: String | AG27: 10 | AO27: 数字文字列
A28: 5 | B28: firstName | N28: ユーザー名 | W28: 全角文字列 | AC28: String | AG28: 20
A29: 6 | B29: firstNameKana | N29: ユーザー名（かな） | W29: 全角文字列 | AC29: String | AG29: 20
A30: 7 | B30: lastName | N30: ユーザー姓 | W30: 全角文字列 | AC30: String | AG30: 10
A31: 8 | B31: lastNameKana | N31: ユーザー姓（かな） | W31: 全角文字列 | AC31: String | AG31: 10
A32: 9 | B32: photoAddress | N32: 写真の住所 | W32: 半角文字列 | AC32: String | AG32: 255
A33: 10 | B33: pwd | N33: パスワード | W33: 半角文字列 | AC33: String | AG33: 20
A34: 11 | B34: sex | N34: 性別 | W34: 半角文字列 | AC34: String | AG34: 1 | AO34: 数字文字列
A35: 12 | B35: userCd | N35: ユーザーコード | W35: 半角文字列 | AC35: String | AG35: 10 | AO35: 数字文字列
A36: 13 | B36: userMail | N36: ユーザーメール | W36: 半角文字列 | AC36: String | AG36: 255
A37: 14 | B37: userStatus | N37: ユーザーステータス | W37: 半角文字列 | AC37: String | AG37: 1 | AO37: 数字文字列
A38: 15 | B38: userTel | N38: ユーザー電話番号 | W38: 半角文字列 | AC38: String | AG38: 11 | AO38: 数字文字列
A39: JSON様式
C41: {
C42: "code": 200,
C43: "message": "操作成功",
C44: "data": {
C45: "A0303Vo": {
...

Sheet 異常とエラー
A1: IF詳細設計書 | S1: API倫理名 | X1: =改訂履歴!X1 -> 管理者情報取得API | AL1: APIID | AQ1: =改訂履歴!AQ1 -> FN1009_004 | BA1: 作成者 | BE1: =改訂履歴!O6 -> 熊 | BL1: 作成日 | BP1: 45680 | BW1: リクエストメゾンド
A2: =AQ1&"_"&X1 -> FN1009_004_管理者情報取得API | S2: API物理名 | X2: =改訂履歴!X2 -> /adminList/getUserInfo | AL2: HTTPメソッド | AQ2: =改訂履歴!AQ2 -> POST | BA2: 更新者 | BL2: 更新日 | BW2: POST | BX2: GET | BY2: DELETE | BZ2: PUT
A4: リクエストメゾンド | E4: =IN.OUTとjson様式!E4 -> POST | J4: swaggerURL | P4: =IN.OUTとjson様式!P4 -> http://localhost:8088/swagger-ui.html#/admin-list-controller/getUserInfoUsingPOST
A5: out
A6: NO. | B6: code | G6: message | W6: 説明
A7: 1 | B7: 200 | G7: 操作成功
A8: 2 | B8: 500 | G8: 操作失敗
A9: 3 | B9: 404 | G9: パラメータチェック失敗
B10: JSON様式 | AC10: タイプ | AK10: 説明
B11: {
B12: "code": 200,
B13: "data": [
B14: {
B15: }
B16: ],
B17: "message": "操作成功"
B18: }

Sheet 詳細処理仕様
A1: IF詳細設計書 | S1: API倫理名 | X1: =改訂履歴!X1 -> 管理者情報取得API | AL1: APIID | AQ1: =改訂履歴!AQ1 -> FN1009_004 | BA1: 作成者 | BE1: =改訂履歴!O6 -> 熊 | BL1: 作成日 | BP1: =改訂履歴!G6 -> 45680
A2: =AQ1&"_"&X1 -> FN1009_004_管理者情報取得API | S2: API物理名 | X2: =改訂履歴!X2 -> /adminList/getUserInfo | AL2: HTTPメソッド | AQ2: =改訂履歴!AQ2 -> POST | BA2: 更新者 | BL2: 更新日
A6: 管理者情報を取得するAPI
A9: 詳細処理仕様
A10: コントローラー | F10: AdminListController | Z10: メゾンド | AE10: getUserInfo
A12: 1 | C12: ユーザー情報取得
D13: AdminListService.getUserInfoを利用し、ユーザーIDでユーザー情報を取得する。
D14: 処理内容はシート「参考するサービス」を参照する。
D15: AdminListService.getUserInfoのパラメータ
D16: no | G16: パラメータ | X16: タイプ | AI16: 必須
D17: 1 | G17: userID | X17: String | AI17: 〇
D18: リターン
D19: タイプ | O19: 備考
D20: Integer | O20: 更新件数
A22: 2 | C22: ユーザー情報を返す
D23: ユーザー情報をA0303Voに格納して返す。

Sheet 参考するサービス
A1: IF詳細設計書 | S1: API倫理名 | X1: =改訂履歴!X1 -> 管理者情報取得API | AL1: APIID | AQ1: =改訂履歴!AQ1 -> FN1009_004 | BA1: 作成者 | BE1: =改訂履歴!O6 -> 熊 | BL1: 作成日 | BP1: =改訂履歴!G6 -> 45680
A2: =AQ1&"_"&X1 -> FN1009_004_管理者情報取得API | S2: API物理名 | X2: =改訂履歴!X2 -> /adminList/getUserInfo | AL2: HTTPメソッド | AQ2: =改訂履歴!AQ2 -> POST | BA2: 更新者 | BL2: 更新日
A5: サービス | F5: AdminListService | Z5: メゾンド | AE5: getUserInfo
A7: 1 | C7: ユーザー情報取得
D8: UserTblMapper.getUserInfoByUserIDを利用し、ユーザー情報を取得する。
D9: 処理内容はシート「参考するMapper」を参照する。
D10: UserTblMapper.getUserInfoByUserIDのパラメータ
D11: no | G11: パラメータ | X11: タイプ | AI11: 必須
D12: 1 | G12: userID | X12: String | AI12: 〇
A14: 2 | C14: ユーザー情報を返す

Sheet 参考するMapper
A1: IF詳細設計書 | S1: API倫理名 | X1: =改訂履歴!X1 -> 管理者情報取得API | AL1: APIID | AQ1: =改訂履歴!AQ1 -> FN1009_004 | BA1: 作成者 | BE1: =改訂履歴!O6 -> 熊 | BL1: 作成日 | BP1: =改訂履歴!G6 -> 45680 | BW1: select
A2: =AQ1&"_"&X1 -> FN1009_004_管理者情報取得API | S2: API物理名 | X2: =改訂履歴!X2 -> /adminList/getUserInfo | AL2: HTTPメソッド | AQ2: =改訂履歴!AQ2 -> POST | BA2: 更新者 | BL2: 更新日 | BW2: update
BW3: insert
BW4: Delete
A5: MapperId | F5: UserTblMapper | W5: クエリーId | AB5: getUserInfoByUserID | AM5: クエリータイプ | AR5: select | AX5: テーブル | BD5: USER_TBL
A6: IN
A7: パラメータ | AH7: where条件 | AQ7: 説明
A8: userID | AH8: ○
A9: OUT | G9: UserTblEntity
A10: 列名 | S10: 物理名 | AH10: 説明
A11: USER_ID | S11: userID
A12: PWD | S12: pwd
A13: COMPANY_ID | S13: companyID
A14: COMPANY_NM | S14: companyNm
A15: AUTHORITY | S15: authority
A16: FIRST_NAME_KANA | S16: firstNameKana
A17: FIRST_NAME | S17: firstName
A18: LAST_NAME_KANA | S18: lastNameKana
A19: LAST_NAME | S19: lastName
A20: SEX | S20: sex
A21: COUNTRY_ZIP | S21: countryZip
A22: USER_TEL | S22: userTel
... A30: UPDATE_BY | S30: updateBy
A32: 検索条件
B33: USER_STATUS | N33: = | Q33: '0'
B34: DEL_FLG | N34: = | Q34: '0'（未削除）
B35: USER_ID | N35: = | Q35: userID
